[2022-07-21 06:15:06] [INFO    ] discord.client: logging in using static token
[2022-07-21 06:15:06] [WARNING ] discord.http: We are being rate limited. Retrying in 12.78 seconds. Handled under the bucket "None:894451313818099783:/applications/{application_id}/guilds/{guild_id}/commands"
Stack (most recent call last):
  File "main.py", line 102, in <module>
    client.run(os.environ.get('TOKEN'), log_handler=handler, log_level=logging.INFO)
  File "/home/runner/testing/venv/lib/python3.8/site-packages/discord/client.py", line 872, in run
    asyncio.run(runner())
  File "/nix/store/p21fdyxqb3yqflpim7g8s1mymgpnqiv7-python3-3.8.12/lib/python3.8/asyncio/runners.py", line 44, in run
    return loop.run_until_complete(main)
  File "/nix/store/p21fdyxqb3yqflpim7g8s1mymgpnqiv7-python3-3.8.12/lib/python3.8/asyncio/base_events.py", line 603, in run_until_complete
    self.run_forever()
  File "/nix/store/p21fdyxqb3yqflpim7g8s1mymgpnqiv7-python3-3.8.12/lib/python3.8/asyncio/base_events.py", line 570, in run_forever
    self._run_once()
  File "/nix/store/p21fdyxqb3yqflpim7g8s1mymgpnqiv7-python3-3.8.12/lib/python3.8/asyncio/base_events.py", line 1859, in _run_once
    handle._run()
  File "/nix/store/p21fdyxqb3yqflpim7g8s1mymgpnqiv7-python3-3.8.12/lib/python3.8/asyncio/events.py", line 81, in _run
    self._context.run(self._callback, *self._args)
  File "/home/runner/testing/venv/lib/python3.8/site-packages/discord/client.py", line 847, in runner
    await self.start(token, reconnect=reconnect)
  File "/home/runner/testing/venv/lib/python3.8/site-packages/discord/client.py", line 780, in start
    await self.login(token)
  File "/home/runner/testing/venv/lib/python3.8/site-packages/discord/client.py", line 632, in login
    await self.setup_hook()
  File "main.py", line 42, in setup_hook
    await self.tree.sync(guild=MY_GUILD)
  File "/home/runner/testing/venv/lib/python3.8/site-packages/discord/app_commands/tree.py", line 991, in sync
    data = await self._http.bulk_upsert_guild_commands(self.client.application_id, guild.id, payload=payload)
  File "/home/runner/testing/venv/lib/python3.8/site-packages/discord/http.py", line 475, in request
    _log.warning(fmt, retry_after, bucket, stack_info=True)
[2022-07-21 06:15:20] [INFO    ] discord.gateway: Shard ID None has sent the IDENTIFY payload.
[2022-07-21 06:15:20] [INFO    ] discord.gateway: Shard ID None has connected to Gateway (Session ID: 883810ea7fa2054b1989b75a921bdc65).
[2022-07-21 06:15:22] [ERROR   ] discord.client: Ignoring exception in on_ready
Traceback (most recent call last):
  File "/home/runner/testing/venv/lib/python3.8/site-packages/discord/client.py", line 456, in _run_event
    await coro(*args, **kwargs)
  File "/home/runner/testing/cogs/Misc.py", line 62, in on_ready
    self.bot.launch_time = datetime.datetime.utcnow()
NameError: name 'datetime' is not defined
